Mon Apr  7 17:31:12 EDT 2025
I ran on:
SLURM_NODELIST=spdr18
Moving to /home/km3nc/babylm
setting up conda
no change     /usr/local/sw/anaconda/anaconda3/condabin/conda
no change     /usr/local/sw/anaconda/anaconda3/bin/conda
no change     /usr/local/sw/anaconda/anaconda3/bin/conda-env
no change     /usr/local/sw/anaconda/anaconda3/bin/activate
no change     /usr/local/sw/anaconda/anaconda3/bin/deactivate
no change     /usr/local/sw/anaconda/anaconda3/etc/profile.d/conda.sh
no change     /usr/local/sw/anaconda/anaconda3/etc/fish/conf.d/conda.fish
no change     /usr/local/sw/anaconda/anaconda3/shell/condabin/Conda.psm1
no change     /usr/local/sw/anaconda/anaconda3/shell/condabin/conda-hook.ps1
no change     /usr/local/sw/anaconda/anaconda3/lib/python3.9/site-packages/xontrib/conda.xsh
no change     /usr/local/sw/anaconda/anaconda3/etc/profile.d/conda.csh
no change     /home/km3nc/.bashrc
No action taken.
checking pip installs
WARNING: No metadata found in /usr/local/sw/anaconda/anaconda3/lib/python3.9/site-packages
minicons==0.3.22
Running python script
/usr/local/sw/anaconda/anaconda3/lib/python3.9/site-packages/torch/utils/_pytree.py:185: FutureWarning: optree is installed but the version is too old to support PyTorch Dynamo in C++ pytree. C++ pytree support is disabled. Please consider upgrading optree using `python3 -m pip install --upgrade 'optree>=0.13.0'`.
  warnings.warn(
W0407 17:31:16.031644 2648910 site-packages/torch/distributed/run.py:792] 
W0407 17:31:16.031644 2648910 site-packages/torch/distributed/run.py:792] *****************************************
W0407 17:31:16.031644 2648910 site-packages/torch/distributed/run.py:792] Setting OMP_NUM_THREADS environment variable for each process to be 1 in default, to avoid your system being overloaded, please further tune the variable for optimal performance in your application as needed. 
W0407 17:31:16.031644 2648910 site-packages/torch/distributed/run.py:792] *****************************************
/usr/local/sw/anaconda/anaconda3/lib/python3.9/site-packages/torch/utils/_pytree.py:185: FutureWarning: optree is installed but the version is too old to support PyTorch Dynamo in C++ pytree. C++ pytree support is disabled. Please consider upgrading optree using `python3 -m pip install --upgrade 'optree>=0.13.0'`.
  warnings.warn(
/usr/local/sw/anaconda/anaconda3/lib/python3.9/site-packages/torch/utils/_pytree.py:185: FutureWarning: optree is installed but the version is too old to support PyTorch Dynamo in C++ pytree. C++ pytree support is disabled. Please consider upgrading optree using `python3 -m pip install --upgrade 'optree>=0.13.0'`.
  warnings.warn(
2025-04-07 17:31:18.750505: I tensorflow/core/util/port.cc:113] oneDNN custom operations are on. You may see slightly different numerical results due to floating-point round-off errors from different computation orders. To turn them off, set the environment variable `TF_ENABLE_ONEDNN_OPTS=0`.
2025-04-07 17:31:18.750506: I tensorflow/core/util/port.cc:113] oneDNN custom operations are on. You may see slightly different numerical results due to floating-point round-off errors from different computation orders. To turn them off, set the environment variable `TF_ENABLE_ONEDNN_OPTS=0`.
2025-04-07 17:31:18.786905: E external/local_xla/xla/stream_executor/cuda/cuda_dnn.cc:9261] Unable to register cuDNN factory: Attempting to register factory for plugin cuDNN when one has already been registered
2025-04-07 17:31:18.786916: E external/local_xla/xla/stream_executor/cuda/cuda_dnn.cc:9261] Unable to register cuDNN factory: Attempting to register factory for plugin cuDNN when one has already been registered
2025-04-07 17:31:18.786932: E external/local_xla/xla/stream_executor/cuda/cuda_fft.cc:607] Unable to register cuFFT factory: Attempting to register factory for plugin cuFFT when one has already been registered
2025-04-07 17:31:18.786940: E external/local_xla/xla/stream_executor/cuda/cuda_fft.cc:607] Unable to register cuFFT factory: Attempting to register factory for plugin cuFFT when one has already been registered
2025-04-07 17:31:18.787906: E external/local_xla/xla/stream_executor/cuda/cuda_blas.cc:1515] Unable to register cuBLAS factory: Attempting to register factory for plugin cuBLAS when one has already been registered
2025-04-07 17:31:18.787925: E external/local_xla/xla/stream_executor/cuda/cuda_blas.cc:1515] Unable to register cuBLAS factory: Attempting to register factory for plugin cuBLAS when one has already been registered
2025-04-07 17:31:18.793245: I tensorflow/core/platform/cpu_feature_guard.cc:182] This TensorFlow binary is optimized to use available CPU instructions in performance-critical operations.
To enable the following instructions: AVX2 AVX512F AVX512_VNNI FMA, in other operations, rebuild TensorFlow with the appropriate compiler flags.
2025-04-07 17:31:18.793251: I tensorflow/core/platform/cpu_feature_guard.cc:182] This TensorFlow binary is optimized to use available CPU instructions in performance-critical operations.
To enable the following instructions: AVX2 AVX512F AVX512_VNNI FMA, in other operations, rebuild TensorFlow with the appropriate compiler flags.
2025-04-07 17:31:19.699837: W tensorflow/compiler/tf2tensorrt/utils/py_utils.cc:38] TF-TRT Warning: Could not find TensorRT
2025-04-07 17:31:19.699849: W tensorflow/compiler/tf2tensorrt/utils/py_utils.cc:38] TF-TRT Warning: Could not find TensorRT
Traceback (most recent call last):
  File "/home/km3nc/babylm/train.py", line 41, in <module>
Traceback (most recent call last):
  File "/home/km3nc/babylm/train.py", line 41, in <module>
    tokenizer = GPT2TokenizerFast(tokenizer_file= str(tokenizer_path))
  File "/usr/local/sw/anaconda/anaconda3/lib/python3.9/site-packages/transformers/models/gpt2/tokenization_gpt2_fast.py", line 99, in __init__
    tokenizer = GPT2TokenizerFast(tokenizer_file= str(tokenizer_path))
  File "/usr/local/sw/anaconda/anaconda3/lib/python3.9/site-packages/transformers/models/gpt2/tokenization_gpt2_fast.py", line 99, in __init__
    super().__init__(
  File "/usr/local/sw/anaconda/anaconda3/lib/python3.9/site-packages/transformers/tokenization_utils_fast.py", line 116, in __init__
    super().__init__(
  File "/usr/local/sw/anaconda/anaconda3/lib/python3.9/site-packages/transformers/tokenization_utils_fast.py", line 116, in __init__
    fast_tokenizer = TokenizerFast.from_file(fast_tokenizer_file)
Exception: No such file or directory (os error 2)
    fast_tokenizer = TokenizerFast.from_file(fast_tokenizer_file)
Exception: No such file or directory (os error 2)
E0407 17:31:22.866691 2648910 site-packages/torch/distributed/elastic/multiprocessing/api.py:869] failed (exitcode: 1) local_rank: 0 (pid: 2648919) of binary: /usr/local/sw/anaconda/anaconda3/bin/python
Traceback (most recent call last):
  File "/usr/local/sw/anaconda/anaconda3/bin/torchrun", line 8, in <module>
    sys.exit(main())
  File "/usr/local/sw/anaconda/anaconda3/lib/python3.9/site-packages/torch/distributed/elastic/multiprocessing/errors/__init__.py", line 355, in wrapper
    return f(*args, **kwargs)
  File "/usr/local/sw/anaconda/anaconda3/lib/python3.9/site-packages/torch/distributed/run.py", line 918, in main
    run(args)
  File "/usr/local/sw/anaconda/anaconda3/lib/python3.9/site-packages/torch/distributed/run.py", line 909, in run
    elastic_launch(
  File "/usr/local/sw/anaconda/anaconda3/lib/python3.9/site-packages/torch/distributed/launcher/api.py", line 138, in __call__
    return launch_agent(self._config, self._entrypoint, list(args))
  File "/usr/local/sw/anaconda/anaconda3/lib/python3.9/site-packages/torch/distributed/launcher/api.py", line 269, in launch_agent
    raise ChildFailedError(
torch.distributed.elastic.multiprocessing.errors.ChildFailedError: 
============================================================
train.py FAILED
------------------------------------------------------------
Failures:
[1]:
  time      : 2025-04-07_17:31:22
  host      : spdr18.cluster
  rank      : 1 (local_rank: 1)
  exitcode  : 1 (pid: 2648920)
  error_file: <N/A>
  traceback : To enable traceback see: https://pytorch.org/docs/stable/elastic/errors.html
------------------------------------------------------------
Root Cause (first observed failure):
[0]:
  time      : 2025-04-07_17:31:22
  host      : spdr18.cluster
  rank      : 0 (local_rank: 0)
  exitcode  : 1 (pid: 2648919)
  error_file: <N/A>
  traceback : To enable traceback see: https://pytorch.org/docs/stable/elastic/errors.html
============================================================
Command exited with non-zero status 1
	Command being timed: "torchrun --nproc_per_node=2 train.py"
	User time (seconds): 11.68
	System time (seconds): 2.34
	Percent of CPU this job got: 164%
	Elapsed (wall clock) time (h:mm:ss or m:ss): 0:08.55
	Average shared text size (kbytes): 0
	Average unshared data size (kbytes): 0
	Average stack size (kbytes): 0
	Average total size (kbytes): 0
	Maximum resident set size (kbytes): 1094788
	Average resident set size (kbytes): 0
	Major (requiring I/O) page faults: 455
	Minor (reclaiming a frame) page faults: 381513
	Voluntary context switches: 35782
	Involuntary context switches: 167
	Swaps: 0
	File system inputs: 0
	File system outputs: 88
	Socket messages sent: 0
	Socket messages received: 0
	Signals delivered: 0
	Page size (bytes): 4096
	Exit status: 1
